<?xml version="1.0" encoding="UTF-8"?>
<testng-results ignored="4" total="8" passed="2" failed="2" skipped="0">
  <reporter-output>
    <line>
      <![CDATA[A method is runing]]>
    </line>
    <line>
      <![CDATA[D method is runing]]>
    </line>
  </reporter-output>
  <suite started-at="2022-11-19T12:01:50 IST" name="Failed suite [Failed suite [Suite]]" finished-at="2022-11-19T12:01:50 IST" duration-ms="170">
    <groups>
      <group name="id">
        <method signature="Test3.A()[pri:0, instance:testNgGroupingXml.Test3@26e356f0]" name="A" class="testNgGroupingXml.Test3"/>
        <method signature="Test3.D()[pri:0, instance:testNgGroupingXml.Test3@26e356f0]" name="D" class="testNgGroupingXml.Test3"/>
        <method signature="Test4.G()[pri:0, instance:testNgGroupingXml.Test4@3c7f66c4]" name="G" class="testNgGroupingXml.Test4"/>
        <method signature="Test4.I()[pri:0, instance:testNgGroupingXml.Test4@3c7f66c4]" name="I" class="testNgGroupingXml.Test4"/>
      </group> <!-- id -->
    </groups>
    <test started-at="2022-11-19T12:01:50 IST" name="Test(failed)(failed)" finished-at="2022-11-19T12:01:50 IST" duration-ms="170">
      <class name="testNgGroupingXml.Test4">
        <test-method signature="G()[pri:0, instance:testNgGroupingXml.Test4@3c7f66c4]" started-at="2022-11-19T12:01:50 IST" name="G" finished-at="2022-11-19T12:01:50 IST" duration-ms="28" status="FAIL">
          <exception class="java.lang.AssertionError">
            <message>
              <![CDATA[null]]>
            </message>
            <full-stacktrace>
              <![CDATA[java.lang.AssertionError: null
at org.testng.Assert.fail(Assert.java:99)
at org.testng.Assert.fail(Assert.java:106)
at testNgGroupingXml.Test4.G(Test4.java:11)
at java.base/jdk.internal.reflect.NativeMethodAccessorImpl.invoke0(Native Method)
at java.base/jdk.internal.reflect.NativeMethodAccessorImpl.invoke(NativeMethodAccessorImpl.java:62)
at java.base/jdk.internal.reflect.DelegatingMethodAccessorImpl.invoke(DelegatingMethodAccessorImpl.java:43)
at java.base/java.lang.reflect.Method.invoke(Method.java:566)
at org.testng.internal.MethodInvocationHelper.invokeMethod(MethodInvocationHelper.java:133)
at org.testng.internal.TestInvoker.invokeMethod(TestInvoker.java:598)
at org.testng.internal.TestInvoker.invokeTestMethod(TestInvoker.java:173)
at org.testng.internal.MethodRunner.runInSequence(MethodRunner.java:46)
at org.testng.internal.TestInvoker$MethodInvocationAgent.invoke(TestInvoker.java:824)
at org.testng.internal.TestInvoker.invokeTestMethods(TestInvoker.java:146)
at org.testng.internal.TestMethodWorker.invokeTestMethods(TestMethodWorker.java:146)
at org.testng.internal.TestMethodWorker.run(TestMethodWorker.java:128)
at java.base/java.util.ArrayList.forEach(ArrayList.java:1541)
at org.testng.TestRunner.privateRun(TestRunner.java:794)
at org.testng.TestRunner.run(TestRunner.java:596)
at org.testng.SuiteRunner.runTest(SuiteRunner.java:377)
at org.testng.SuiteRunner.runSequentially(SuiteRunner.java:371)
at org.testng.SuiteRunner.privateRun(SuiteRunner.java:332)
at org.testng.SuiteRunner.run(SuiteRunner.java:276)
at org.testng.SuiteRunnerWorker.runSuite(SuiteRunnerWorker.java:53)
at org.testng.SuiteRunnerWorker.run(SuiteRunnerWorker.java:96)
at org.testng.TestNG.runSuitesSequentially(TestNG.java:1212)
at org.testng.TestNG.runSuitesLocally(TestNG.java:1134)
at org.testng.TestNG.runSuites(TestNG.java:1063)
at org.testng.TestNG.run(TestNG.java:1031)
at org.testng.remote.AbstractRemoteTestNG.run(AbstractRemoteTestNG.java:115)
at org.testng.remote.RemoteTestNG.initAndRun(RemoteTestNG.java:251)
at org.testng.remote.RemoteTestNG.main(RemoteTestNG.java:77)
]]>
            </full-stacktrace>
          </exception> <!-- java.lang.AssertionError -->
          <reporter-output>
          </reporter-output>
        </test-method> <!-- G -->
        <test-method signature="I()[pri:0, instance:testNgGroupingXml.Test4@3c7f66c4]" started-at="2022-11-19T12:01:50 IST" name="I" finished-at="2022-11-19T12:01:50 IST" duration-ms="2" status="FAIL">
          <exception class="java.lang.AssertionError">
            <message>
              <![CDATA[null]]>
            </message>
            <full-stacktrace>
              <![CDATA[java.lang.AssertionError: null
at org.testng.Assert.fail(Assert.java:99)
at org.testng.Assert.fail(Assert.java:106)
at testNgGroupingXml.Test4.I(Test4.java:22)
at java.base/jdk.internal.reflect.NativeMethodAccessorImpl.invoke0(Native Method)
at java.base/jdk.internal.reflect.NativeMethodAccessorImpl.invoke(NativeMethodAccessorImpl.java:62)
at java.base/jdk.internal.reflect.DelegatingMethodAccessorImpl.invoke(DelegatingMethodAccessorImpl.java:43)
at java.base/java.lang.reflect.Method.invoke(Method.java:566)
at org.testng.internal.MethodInvocationHelper.invokeMethod(MethodInvocationHelper.java:133)
at org.testng.internal.TestInvoker.invokeMethod(TestInvoker.java:598)
at org.testng.internal.TestInvoker.invokeTestMethod(TestInvoker.java:173)
at org.testng.internal.MethodRunner.runInSequence(MethodRunner.java:46)
at org.testng.internal.TestInvoker$MethodInvocationAgent.invoke(TestInvoker.java:824)
at org.testng.internal.TestInvoker.invokeTestMethods(TestInvoker.java:146)
at org.testng.internal.TestMethodWorker.invokeTestMethods(TestMethodWorker.java:146)
at org.testng.internal.TestMethodWorker.run(TestMethodWorker.java:128)
at java.base/java.util.ArrayList.forEach(ArrayList.java:1541)
at org.testng.TestRunner.privateRun(TestRunner.java:794)
at org.testng.TestRunner.run(TestRunner.java:596)
at org.testng.SuiteRunner.runTest(SuiteRunner.java:377)
at org.testng.SuiteRunner.runSequentially(SuiteRunner.java:371)
at org.testng.SuiteRunner.privateRun(SuiteRunner.java:332)
at org.testng.SuiteRunner.run(SuiteRunner.java:276)
at org.testng.SuiteRunnerWorker.runSuite(SuiteRunnerWorker.java:53)
at org.testng.SuiteRunnerWorker.run(SuiteRunnerWorker.java:96)
at org.testng.TestNG.runSuitesSequentially(TestNG.java:1212)
at org.testng.TestNG.runSuitesLocally(TestNG.java:1134)
at org.testng.TestNG.runSuites(TestNG.java:1063)
at org.testng.TestNG.run(TestNG.java:1031)
at org.testng.remote.AbstractRemoteTestNG.run(AbstractRemoteTestNG.java:115)
at org.testng.remote.RemoteTestNG.initAndRun(RemoteTestNG.java:251)
at org.testng.remote.RemoteTestNG.main(RemoteTestNG.java:77)
]]>
            </full-stacktrace>
          </exception> <!-- java.lang.AssertionError -->
          <reporter-output>
          </reporter-output>
        </test-method> <!-- I -->
      </class> <!-- testNgGroupingXml.Test4 -->
      <class name="testNgGroupingXml.Test3">
        <test-method signature="A()[pri:0, instance:testNgGroupingXml.Test3@26e356f0]" started-at="2022-11-19T12:01:50 IST" name="A" finished-at="2022-11-19T12:01:50 IST" duration-ms="10" status="PASS">
          <reporter-output>
            <line>
              <![CDATA[A method is runing]]>
            </line>
          </reporter-output>
        </test-method> <!-- A -->
        <test-method signature="D()[pri:0, instance:testNgGroupingXml.Test3@26e356f0]" started-at="2022-11-19T12:01:50 IST" name="D" finished-at="2022-11-19T12:01:50 IST" duration-ms="6" status="PASS">
          <reporter-output>
            <line>
              <![CDATA[D method is runing]]>
            </line>
          </reporter-output>
        </test-method> <!-- D -->
      </class> <!-- testNgGroupingXml.Test3 -->
    </test> <!-- Test(failed)(failed) -->
  </suite> <!-- Failed suite [Failed suite [Suite]] -->
</testng-results>
